FAIL selftest.test1 running test selftest
Traceback (most recent call last):
  File "/home/apw/views/autotest-r99-dev/current/bin/test.py", line 54, in __exec
    self.execute(*parameters)
  File "/home/apw/views/autotest-r99-dev/current/tests/selftest/selftest.py", line 47, in execute
    self.__throw(*args)
  File "/home/apw/views/autotest-r99-dev/current/tests/selftest/selftest.py", line 35, in __throw
    __does_not_exist = __does_not_exist_either
NameError: global name '_selftest__does_not_exist_either' is not defined


--SELFTEST-- exit 0
